Workbook

Sheet Instrucciones
B2: MONITOR DE CRUCES DE MEDIAS MÓVILES — GUÍA RÁPIDA
B4: Este libro es una PLANTILLA FUNCIONAL con datos SIMULADOS (celdas en azul/amarillo).
B5: No contiene cotizaciones reales. Sustituye los datos simulados por una conexión real
B6: (Power Query / API / bróker) siguiendo la especificación técnica adjunta (documento Word).
B8: HOJAS DEL LIBRO
B9: 1. Monitorización → tabla principal de activos, medias móviles y alertas recientes.
B10: 2. Niveles_Importancia → reglas que definen la importancia de cada tipo de cruce.
B11: 3. Universo_Activos → listado maestro de activos seleccionables (plantilla a 1000 filas).
B12: 4. Historico_Alertas → registro consolidado de todos los cruces detectados.
B14: CÓMO AÑADIR/QUITAR UN ACTIVO
B15: - En 'Monitorización', columna 'Nombre (seleccionar)', usa la lista desplegable：
B16: solo permite elegir activos ya dados de alta en 'Universo_Activos' con Estado = Activo.
... B47: - Las celdas con fondo AMARILLO requieren tu atención o configuración.

Sheet Monitorizacion
B2: MONITOR DE CRUCES DE MEDIAS MOVILES
B3: Configuracion global de las 4 medias moviles (se aplican a todos los activos y time frames):
B4: Media | C4: Tipo | D4: Periodo | E4: Etiqueta
B5: MA 1 | C5: EMA | D5: 9 | E5: =C5&" "&D5 -> EMA 9
B6: MA 2 | C6: EMA | D6: 20 | E6: =C6&" "&D6 -> EMA 20
B7: MA 3 | C7: EMA | D7: 50 | E7: =C7&" "&D7 -> EMA 50
B8: MA 4 | C8: EMA | D8: 150 | E8: =C8&" "&D8 -> EMA 150
A11: No | B11: Nombre (seleccionar) | C11: Categoria | D11: Mercado | E11: Ticker | F11: ISIN | G11: Precio actual | H11: % Dia | I11: % Semana | J11: % Mes | K11: % Ano | L11: % 12M | M11: Precio 15m (act) | N11: Precio 15m (ant) | O11: MA1 15m (act) | P11: MA1 15m (ant) | Q11: MA2 15m (act) | R11: MA2 15m (ant) | S11: MA3 15m (act) | T11: MA3 15m (ant) | U11: MA4 15m (act) | V11: MA4 15m (ant) | W11: Cruce Vela/MA1 15m | X11: Cruce MA1/MA2 15m | Y11: Precio 1h (act) | Z11: Precio 1h (ant) | AA11: MA1 1h (act) | AB11: MA1 1h (ant) | AC11: MA2 1h (act) | AD11: MA2 1h (ant) | AE11: MA3 1h (act) | AF11: MA3 1h (ant) | AG11: MA4 1h (act) | AH11: MA4 1h (ant) | AI11: Cruce Vela/MA1 1h | AJ11: Cruce MA1/MA2 1h | AK11: Nivel importancia | AL11: Mensaje generado | AM11: ID unico (dedup)
A12: 1 | B12: Euro / Dolar | C12: =IFERROR(INDEX(Universo_Activos!$A$3:$A$1022,MATCH(B12,Universo_Activos!$C$3:$C$1022,0)),"") -> Forex | D12: =IFERROR(INDEX(Universo_Activos!$B$3:$B$1022,MATCH(B12,Universo_Activos!$C$3:$C$1022,0)),"") -> OTC/Interbancario | E12: =IFERROR(INDEX(Universo_Activos!$D$3:$D$1022,MATCH(B12,Universo_Activos!$C$3:$C$1022,0)),"") -> EURUSD | F12: =IFERROR(INDEX(Universo_Activos!$E$3:$E$1022,MATCH(B12,Universo_Activos!$C$3:$C$1022,0)),"") -> N/A (par de divisas, sin ISIN) | G12: 146.67 | H12: 0.0096 | I12: 0.0679 | J12: -0.0055 | K12: 0.0013 | L12: 0.014 | M12: 56.46 | N12: 56.18 | O12: 56.161401 | P12: 56.086751 | Q12: 56.056457 | R12: 56.013978 | S12: 56.006975 | T12: 55.988484 | U12: 55.553532 | V12: 55.541365 | W12: =IF(AND(N12<=P12,M12>O12),"ALCISTA",IF(AND(N12>=P12,M12<O12),"BAJISTA","")) | X12: =IF(AND(P12<=R12,O12>Q12),"ALCISTA",IF(AND(P12>=R12,O12<Q12),"BAJISTA","")) | Y12: 56.46 | Z12: 56.02 | AA12: 56.096826 | AB12: 56.006033 | AC12: 55.957114 | AD12: 55.904179 | AE12: 55.412817 | AF12: 55.370075 | AG12: 54.98329 | AH12: 54.963469 | AI12: =IF(AND(Z12<=AB12,Y12>AA12),"ALCISTA",IF(AND(Z12>=AB12,Y12<AA12),"BAJISTA","")) | AJ12: =IF(AND(AB12<=AD12,AA12>AC12),"ALCISTA",IF(AND(AB12>=AD12,AA12<AC12),"BAJISTA","")) | AK12: =IF(W12<>"",IFERROR(INDEX(Niveles_Importancia!$A$3:$A$30,MATCH("Vela|"&$E$5&"|15 min",Niveles_Importancia!$H$3:$H$30,0)),"Sin clasificar"),IF(X12<>"",IFERROR(INDEX(Niveles_Importancia!$A$3:$A$30,MATCH($E$5&"|"&$E$6&"|15 min",Niveles_Importancia!$H$3:$H$30,0)),"Sin clasificar"),IF(AI12<>"",IFERROR(INDEX(Niveles_Importancia!$A$3:$A$30,MATCH("Vela|"&$E$5&"|1 hora",Niveles_Importancia!$H$3:$H$30,0)),"Sin clasificar"),IF(AJ12<>"",IFERROR(INDEX(Niveles_Importancia!$A$3:$A$30,MATCH($E$5&"|"&$E$6&"|1 hora",Niveles_Importancia!$H$3:$H$30,0)),"Sin clasificar"),"")))) | AL12: =IF(W12<>"","Cruce "&LOWER(W12)&" detectado en "&B12&" ("&D12&"). La vela ha cruzado "&$E$5&" en 15 min. Nivel: "&AK12&". Precio: "&TEXT(M12,"0.00")&". "&TEXT(NOW(),"dd/mm/yyyy hh:mm"),IF(X12<>"","Cruce "&LOWER(X12)&" detectado en "&B12&" ("&D12&"). "&$E$5&" ha cruzado "&$E$6&" en 15 min. Nivel: "&AK12&". "&TEXT(NOW(),"dd/mm/yyyy hh:mm"),IF(AI12<>"","Cruce "&LOWER(AI12)&" detectado en "&B12&" ("&D12&"). La vela ha cruzado "&$E$5&" en 1 hora. Nivel: "&AK12&". "&TEXT(NOW(),"dd/mm/yyyy hh:mm"),IF(AJ12<>"","Cruce "&LOWER(AJ12)&" detectado en "&B12&" ("&D12&"). "&$E$5&" ha cruzado "&$E$6&" en 1 hora. Nivel: "&AK12&". "&TEXT(NOW(),"dd/mm/yyyy hh:mm"),"")))) | AM12: =IF(AL12="","",B12&"|"&IF(W12<>"","15min-VelaMA1",IF(X12<>"","15min-MA1MA2",IF(AI12<>"","1h-VelaMA1","1h-MA1MA2")))&"|"&TEXT(NOW(),"yyyymmddhhmm"))
A13: 2 | B13: Libra / Dolar | C13: =IFERROR(INDEX(Universo_Activos!$A$3:$A$1022,MATCH(B13,Universo_Activos!$C$3:$C$1022,0)),"") -> Forex | D13: =IFERROR(INDEX(Universo_Activos!$B$3:$B$1022,MATCH(B13,Universo_Activos!$C$3:$C$1022,0)),"") -> OTC/Interbancario | E13: =IFERROR(INDEX(Universo_Activos!$D$3:$D$1022,MATCH(B13,Universo_Activos!$C$3:$C$1022,0)),"") -> GBPUSD | F13: =IFERROR(INDEX(Universo_Activos!$E$3:$E$1022,MATCH(B13,Universo_Activos!$C$3:$C$1022,0)),"") -> N/A (par de divisas, sin ISIN) | G13: 28.42 | H13: -0.0058 | I13: -0.0095 | J13: 0.0548 | K13: 0.0031 | L13: 0.0224 | M13: 20.61 | N13: 20.65 | O13: 20.717646 | P13: 20.744558 | Q13: 20.786214 | R13: 20.804762 | S13: 20.899641 | T13: 20.911463 | U13: 21.071023 | V13: 21.077211 | W13: =IF(AND(N13<=P13,M13>O13),"ALCISTA",IF(AND(N13>=P13,M13<O13),"BAJISTA","")) | X13: =IF(AND(P13<=R13,O13>Q13),"ALCISTA",IF(AND(P13>=R13,O13<Q13),"BAJISTA","")) | Y13: 20.61 | Z13: 20.67 | AA13: 20.811387 | AB13: 20.861734 | AC13: 20.943991 | AD13: 20.979148 | AE13: 21.076158 | AF13: 21.095185 | AG13: 21.130188 | AH13: 21.13717 | AI13: =IF(AND(Z13<=AB13,Y13>AA13),"ALCISTA",IF(AND(Z13>=AB13,Y13<AA13),"BAJISTA","")) | AJ13: =IF(AND(AB13<=AD13,AA13>AC13),"ALCISTA",IF(AND(AB13>=AD13,AA13<AC13),"BAJISTA","")) | AK13: =IF(W13<>"",IFERROR(INDEX(Niveles_Importancia!$A$3:$A$30,MATCH("Vela|"&$E$5&"|15 min",Niveles_Importancia!$H$3:$H$30,0)),"Sin clasificar"),IF(X13<>"",IFERROR(INDEX(Niveles_Importancia!$A$3:$A$30,MATCH($E$5&"|"&$E$6&"|15 min",Niveles_Importancia!$H$3:$H$30,0)),"Sin clasificar"),IF(AI13<>"",IFERROR(INDEX(Niveles_Importancia!$A$3:$A$30,MATCH("Vela|"&$E$5&"|1 hora",Niveles_Importancia!$H$3:$H$30,0)),"Sin clasificar"),IF(AJ13<>"",IFERROR(INDEX(Niveles_Importancia!$A$3:$A$30,MATCH($E$5&"|"&$E$6&"|1 hora",Niveles_Importancia!$H$3:$H$30,0)),"Sin clasificar"),"")))) | AL13: =IF(W13<>"","Cruce "&LOWER(W13)&" detectado en "&B13&" ("&D13&"). La vela ha cruzado "&$E$5&" en 15 min. Nivel: "&AK13&". Precio: "&TEXT(M13,"0.00")&". "&TEXT(NOW(),"dd/mm/yyyy hh:mm"),IF(X13<>"","Cruce "&LOWER(X13)&" detectado en "&B13&" ("&D13&"). "&$E$5&" ha cruzado "&$E$6&" en 15 min. Nivel: "&AK13&". "&TEXT(NOW(),"dd/mm/yyyy hh:mm"),IF(AI13<>"","Cruce "&LOWER(AI13)&" detectado en "&B13&" ("&D13&"). La vela ha cruzado "&$E$5&" en 1 hora. Nivel: "&AK13&". "&TEXT(NOW(),"dd/mm/yyyy hh:mm"),IF(AJ13<>"","Cruce "&LOWER(AJ13)&" detectado en "&B13&" ("&D13&"). "&$E$5&" ha cruzado "&$E$6&" en 1 hora. Nivel: "&AK13&". "&TEXT(NOW(),"dd/mm/yyyy hh:mm"),"")))) | AM13: =IF(AL13="","",B13&"|"&IF(W13<>"","15min-VelaMA1",IF(X13<>"","15min-MA1MA2",IF(AI13<>"","1h-VelaMA1","1h-MA1MA2")))&"|"&TEXT(NOW(),"yyyymmddhhmm"))
A14: 3 | B14: Dolar / Yen | C14: =IFERROR(INDEX(Universo_Activos!$A$3:$A$1022,MATCH(B14,Universo_Activos!$C$3:$C$1022,0)),"") -> Forex | D14: =IFERROR(INDEX(Universo_Activos!$B$3:$B$1022,MATCH(B14,Universo_Activos!$C$3:$C$1022,0)),"") -> OTC/Interbancario | E14: =IFERROR(INDEX(Universo_Activos!$D$3:$D$1022,MATCH(B14,Universo_Activos!$C$3:$C$1022,0)),"") -> USDJPY | F14: =IFERROR(INDEX(Universo_Activos!$E$3:$E$1022,MATCH(B14,Universo_Activos!$C$3:$C$1022,0)),"") -> N/A (par de divisas, sin ISIN) | G14: 274.88 | H14: -0.0048 | I14: 0.0769 | J14: -0.0164 | K14: -0.0683 | L14: 0.0207 | M14: 11.952 | N14: 11.934 | O14: 11.973289 | P14: 11.978611 | Q14: 11.998768 | R14: 12.003691 | S14: 12.059888 | T14: 12.064291 | U14: 12.072705 | V14: 12.074325 | W14: =IF(AND(N14<=P14,M14>O14),"ALCISTA",IF(AND(N14>=P14,M14<O14),"BAJISTA","")) | X14: =IF(AND(P14<=R14,O14>Q14),"ALCISTA",IF(AND(P14>=R14,O14<Q14),"BAJISTA","")) | Y14: 11.952 | Z14: 11.972 | AA14: 12.030948 | AB14: 12.050685 | AC14: 12.084821 | AD14: 12.098802 | AE14: 12.064357 | AF14: 12.068943 | AG14: 12.003303 | AH14: 12.003991 | AI14: =IF(AND(Z14<=AB14,Y14>AA14),"ALCISTA",IF(AND(Z14>=AB14,Y14<AA14),"BAJISTA","")) | AJ14: =IF(AND(AB14<=AD14,AA14>AC14),"ALCISTA",IF(AND(AB14>=AD14,AA14<AC14),"BAJISTA","")) | AK14: =IF(W14<>"",IFERROR(INDEX(Niveles_Importancia!$A$3:$A$30,MATCH("Vela|"&$E$5&"|15 min",Niveles_Importancia!$H$3:$H$30,0)),"Sin clasificar"),IF(X14<>"",IFERROR(INDEX(Niveles_Importancia!$A$3:$A$30,MATCH($E$5&"|"&$E$6&"|15 min",Niveles_Importancia!$H$3:$H$30,0)),"Sin clasificar"),IF(AI14<>"",IFERROR(INDEX(Niveles_Importancia!$A$3:$A$30,MATCH("Vela|"&$E$5&"|1 hora",Niveles_Importancia!$H$3:$H$30,0)),"Sin clasificar"),IF(AJ14<>"",IFERROR(INDEX(Niveles_Importancia!$A$3:$A$30,MATCH($E$5&"|"&$E$6&"|1 hora",Niveles_Importancia!$H$3:$H$30,0)),"Sin clasificar"),"")))) | AL14: =IF(W14<>"","Cruce "&LOWER(W14)&" detectado en "&B14&" ("&D14&"). La vela ha cruzado "&$E$5&" en 15 min. Nivel: "&AK14&". Precio: "&TEXT(M14,"0.00")&". "&TEXT(NOW(),"dd/mm/yyyy hh:mm"),IF(X14<>"","Cruce "&LOWER(X14)&" detectado en "&B14&" ("&D14&"). "&$E$5&" ha cruzado "&$E$6&" en 15 min. Nivel: "&AK14&". "&TEXT(NOW(),"dd/mm/yyyy hh:mm"),IF(AI14<>"","Cruce "&LOWER(AI14)&" detectado en "&B14&" ("&D14&"). La vela ha cruzado "&$E$5&" en 1 hora. Nivel: "&AK14&". "&TEXT(NOW(),"dd/mm/yyyy hh:mm"),IF(AJ14<>"","Cruce "&LOWER(AJ14)&" detectado en "&B14&" ("&D14&"). "&$E$5&" ha cruzado "&$E$6&" en 1 hora. Nivel: "&AK14&". "&TEXT(NOW(),"dd/mm/yyyy hh:mm"),"")))) | AM14: =IF(AL14="","",B14&"|"&IF(W14<>"","15min-VelaMA1",IF(X14<>"","15min-MA1MA2",IF(AI14<>"","1h-VelaMA1","1h-MA1MA2")))&"|"&TEXT(NOW(),"yyyymmddhhmm"))
A15: 4 | B15: Dolar AUS / Dolar | C15: =IFERROR(INDEX(Universo_Activos!$A$3:$A$1022,MATCH(B15,Universo_Activos!$C$3:$C$1022,0)),"") -> Forex | D15: =IFERROR(INDEX(Universo_Activos!$B$3:$B$1022,MATCH(B15,Universo_Activos!$C$3:$C$1022,0)),"") -> OTC/Interbancario | E15: =IFERROR(INDEX(Universo_Activos!$D$3:$D$1022,MATCH(B15,Universo_Activos!$C$3:$C$1022,0)),"") -> AUDUSD | F15: =IFERROR(INDEX(Universo_Activos!$E$3:$E$1022,MATCH(B15,Universo_Activos!$C$3:$C$1022,0)),"") -> N/A (par de divisas, sin ISIN) | G15: 79.6 | H15: -0.0368 | I15: 0.0753 | J15: 0.0485 | K15: -0.0313 | L15: 0.0616 | M15: 0.71495 | N15: 0.71503 | O15: 0.71480314 | P15: 0.71476643 | Q15: 0.7151176 | R15: 0.71513524 | S15: 0.71567504 | T15: 0.71570463 | U15: 0.71560059 | V15: 0.71560932 | W15: =IF(AND(N15<=P15,M15>O15),"ALCISTA",IF(AND(N15>=P15,M15<O15),"BAJISTA","")) | X15: =IF(AND(P15<=R15,O15>Q15),"ALCISTA",IF(AND(P15>=R15,O15<Q15),"BAJISTA","")) | Y15: 0.71495 | Z15: 0.71429 | AA15: 0.71535407 | AB15: 0.71545509 | AC15: 0.71578358 | AD15: 0.71587132 | AE15: 0.71514216 | AF15: 0.71515 | AG15: 0.71228272 | AH15: 0.71224691 | AI15: =IF(AND(Z15<=AB15,Y15>AA15),"ALCISTA",IF(AND(Z15>=AB15,Y15<AA15),"BAJISTA","")) | AJ15: =IF(AND(AB15<=AD15,AA15>AC15),"ALCISTA",IF(AND(AB15>=AD15,AA15<AC15),"BAJISTA","")) | AK15: =IF(W15<>"",IFERROR(INDEX(Niveles_Importancia!$A$3:$A$30,MATCH("Vela|"&$E$5&"|15 min",Niveles_Importancia!$H$3:$H$30,0)),"Sin clasificar"),IF(X15<>"",IFERROR(INDEX(Niveles_Importancia!$A$3:$A$30,MATCH($E$5&"|"&$E$6&"|15 min",Niveles_Importancia!$H$3:$H$30,0)),"Sin clasificar"),IF(AI15<>"",IFERROR(INDEX(Niveles_Importancia!$A$3:$A$30,MATCH("Vela|"&$E$5&"|1 hora",Niveles_Importancia!$H$3:$H$30,0)),"Sin clasificar"),IF(AJ15<>"",IFERROR(INDEX(Niveles_Importancia!$A$3:$A$30,MATCH($E$5&"|"&$E$6&"|1 hora",Niveles_Importancia!$H$3:$H$30,0)),"Sin clasificar"),"")))) | AL15: =IF(W15<>"","Cruce "&LOWER(W15)&" detectado en "&B15&" ("&D15&"). La vela ha cruzado "&$E$5&" en 15 min. Nivel: "&AK15&". Precio: "&TEXT(M15,"0.00")&". "&TEXT(NOW(),"dd/mm/yyyy hh:mm"),IF(X15<>"","Cruce "&LOWER(X15)&" detectado en "&B15&" ("&D15&"). "&$E$5&" ha cruzado "&$E$6&" en 15 min. Nivel: "&AK15&". "&TEXT(NOW(),"dd/mm/yyyy hh:mm"),IF(AI15<>"","Cruce "&LOWER(AI15)&" detectado en "&B15&" ("&D15&"). La vela ha cruzado "&$E$5&" en 1 hora. Nivel: "&AK15&". "&TEXT(NOW(),"dd/mm/yyyy hh:mm"),IF(AJ15<>"","Cruce "&LOWER(AJ15)&" detectado en "&B15&" ("&D15&"). "&$E$5&" ha cruzado "&$E$6&" en 1 hora. Nivel: "&AK15&". "&TEXT(NOW(),"dd/mm/yyyy hh:mm"),"")))) | AM15: =IF(AL15="","",B15&"|"&IF(W15<>"","15min-VelaMA1",IF(X15<>"","15min-MA1MA2",IF(AI15<>"","1h-VelaMA1","1h-MA1MA2")))&"|"&TEXT(NOW(),"yyyymmddhhmm"))
A16: 5 | B16: Dolar / Dolar CAD | C16: =IFERROR(INDEX(Universo_Activos!$A$3:$A$1022,MATCH(B16,Universo_Activos!$C$3:$C$1022,0)),"") -> Forex | D16: =IFERROR(INDEX(Universo_Activos!$B$3:$B$1022,MATCH(B16,Universo_Activos!$C$3:$C$1022,0)),"") -> OTC/Interbancario | E16: =IFERROR(INDEX(Universo_Activos!$D$3:$D$1022,MATCH(B16,Universo_Activos!$C$3:$C$1022,0)),"") -> USDCAD | F16: =IFERROR(INDEX(Universo_Activos!$E$3:$E$1022,MATCH(B16,Universo_Activos!$C$3:$C$1022,0)),"") -> N/A (par de divisas, sin ISIN) | G16: 180.88 | H16: 0.0586 | I16: -0.0507 | J16: -0.0553 | K16: 0.0653 | L16: 0.0508 | M16: 162.8 | N16: 163.04 | O16: 162.02401 | P16: 161.83001 | Q16: 160.8925 | R16: 160.69171 | S16: 158.41996 | T16: 158.24118 | U16: 150.86605 | V16: 150.70587 | W16: =IF(AND(N16<=P16,M16>O16),"ALCISTA",IF(AND(N16>=P16,M16<O16),"BAJISTA","")) | X16: =IF(AND(P16<=R16,O16>Q16),"ALCISTA",IF(AND(P16>=R16,O16<Q16),"BAJISTA","")) | Y16: 162.8 | Z16: 162.5 | AA16: 160.29189 | AB16: 159.66486 | AC16: 156.64441 | AD16: 155.99646 | AE16: 149.14905 | AF16: 148.59187 | AG16: 142.13655 | AH16: 141.85919 | AI16: =IF(AND(Z16<=AB16,Y16>AA16),"ALCISTA",IF(AND(Z16>=AB16,Y16<AA16),"BAJISTA","")) | AJ16: =IF(AND(AB16<=AD16,AA16>AC16),"ALCISTA",IF(AND(AB16>=AD16,AA16<AC16),"BAJISTA","")) | AK16: =IF(W16<>"",IFERROR(INDEX(Niveles_Importancia!$A$3:$A$30,MATCH("Vela|"&$E$5&"|15 min",Niveles_Importancia!$H$3:$H$30,0)),"Sin clasificar"),IF(X16<>"",IFERROR(INDEX(Niveles_Importancia!$A$3:$A$30,MATCH($E$5&"|"&$E$6&"|15 min",Niveles_Importancia!$H$3:$H$30,0)),"Sin clasificar"),IF(AI16<>"",IFERROR(INDEX(Niveles_Importancia!$A$3:$A$30,MATCH("Vela|"&$E$5&"|1 hora",Niveles_Importancia!$H$3:$H$30,0)),"Sin clasificar"),IF(AJ16<>"",IFERROR(INDEX(Niveles_Importancia!$A$3:$A$30,MATCH($E$5&"|"&$E$6&"|1 hora",Niveles_Importancia!$H$3:$H$30,0)),"Sin clasificar"),"")))) | AL16: =IF(W16<>"","Cruce "&LOWER(W16)&" detectado en "&B16&" ("&D16&"). La vela ha cruzado "&$E$5&" en 15 min. Nivel: "&AK16&". Precio: "&TEXT(M16,"0.00")&". "&TEXT(NOW(),"dd/mm/yyyy hh:mm"),IF(X16<>"","Cruce "&LOWER(X16)&" detectado en "&B16&" ("&D16&"). "&$E$5&" ha cruzado "&$E$6&" en 15 min. Nivel: "&AK16&". "&TEXT(NOW(),"dd/mm/yyyy hh:mm"),IF(AI16<>"","Cruce "&LOWER(AI16)&" detectado en "&B16&" ("&D16&"). La vela ha cruzado "&$E$5&" en 1 hora. Nivel: "&AK16&". "&TEXT(NOW(),"dd/mm/yyyy hh:mm"),IF(AJ16<>"","Cruce "&LOWER(AJ16)&" detectado en "&B16&" ("&D16&"). "&$E$5&" ha cruzado "&$E$6&" en 1 hora. Nivel: "&AK16&". "&TEXT(NOW(),"dd/mm/yyyy hh:mm"),"")))) | AM16: =IF(AL16="","",B16&"|"&IF(W16<>"","15min-VelaMA1",IF(X16<>"","15min-MA1MA2",IF(AI16<>"","1h-VelaMA1","1h-MA1MA2")))&"|"&TEXT(NOW(),"yyyymmddhhmm"))
A17: 6 | B17: Dolar / Franco | C17: =IFERROR(INDEX(Universo_Activos!$A$3:$A$1022,MATCH(B17,Universo_Activos!$C$3:$C$1022,0)),"") -> Forex | D17: =IFERROR(INDEX(Universo_Activos!$B$3:$B$1022,MATCH(B17,Universo_Activos!$C$3:$C$1022,0)),"") -> OTC/Interbancario | E17: =IFERROR(INDEX(Universo_Activos!$D$3:$D$1022,MATCH(B17,Universo_Activos!$C$3:$C$1022,0)),"") -> USDCHF | F17: =IFERROR(INDEX(Universo_Activos!$E$3:$E$1022,MATCH(B17,Universo_Activos!$C$3:$C$1022,0)),"") -> N/A (par de divisas, sin ISIN) | G17: 39.26 | H17: -0.0435 | I17: 0.0095 | J17: 0.0564 | K17: 0.0183 | L17: -0.0352 | M17: 0.80242 | N17: 0.80229 | O17: 0.80244849 | P17: 0.80245561 | Q17: 0.80235728 | R17: 0.80235067 | S17: 0.80204281 | T17: 0.80202741 | U17: 0.80111374 | V17: 0.8010962 | W17: =IF(AND(N17<=P17,M17>O17),"ALCISTA",IF(AND(N17>=P17,M17<O17),"BAJISTA","")) | X17: =IF(AND(P17<=R17,O17>Q17),"ALCISTA",IF(AND(P17>=R17,O17<Q17),"BAJISTA","")) | Y17: 0.80242 | Z17: 0.80265 | AA17: 0.80229569 | AB17: 0.80226461 | AC17: 0.80179317 | AD17: 0.80172718 | AE17: 0.8014239 | AF17: 0.80138324 | AG17: 0.80419493 | AH17: 0.80421876 | AI17: =IF(AND(Z17<=AB17,Y17>AA17),"ALCISTA",IF(AND(Z17>=AB17,Y17<AA17),"BAJISTA","")) | AJ17: =IF(AND(AB17<=AD17,AA17>AC17),"ALCISTA",IF(AND(AB17>=AD17,AA17<AC17),"BAJISTA","")) | AK17: =IF(W17<>"",IFERROR(INDEX(Niveles_Importancia!$A$3:$A$30,MATCH("Vela|"&$E$5&"|15 min",Niveles_Importancia!$H$3:$H$30,0)),"Sin clasificar"),IF(X17<>"",IFERROR(INDEX(Niveles_Importancia!$A$3:$A$30,MATCH($E$5&"|"&$E$6&"|15 min",Niveles_Importancia!$H$3:$H$30,0)),"Sin clasificar"),IF(AI17<>"",IFERROR(INDEX(Niveles_Importancia!$A$3:$A$30,MATCH("Vela|"&$E$5&"|1 hora",Niveles_Importancia!$H$3:$H$30,0)),"Sin clasificar"),IF(AJ17<>"",IFERROR(INDEX(Niveles_Importancia!$A$3:$A$30,MATCH($E$5&"|"&$E$6&"|1 hora",Niveles_Importancia!$H$3:$H$30,0)),"Sin clasificar"),"")))) | AL17: =IF(W17<>"","Cruce "&LOWER(W17)&" detectado en "&B17&" ("&D17&"). La vela ha cruzado "&$E$5&" en 15 min. Nivel: "&AK17&". Precio: "&TEXT(M17,"0.00")&". "&TEXT(NOW(),"dd/mm/yyyy hh:mm"),IF(X17<>"","Cruce "&LOWER(X17)&" detectado en "&B17&" ("&D17&"). "&$E$5&" ha cruzado "&$E$6&" en 15 min. Nivel: "&AK17&". "&TEXT(NOW(),"dd/mm/yyyy hh:mm"),IF(AI17<>"","Cruce "&LOWER(AI17)&" detectado en "&B17&" ("&D17&"). La vela ha cruzado "&$E$5&" en 1 hora. Nivel: "&AK17&". "&TEXT(NOW(),"dd/mm/yyyy hh:mm"),IF(AJ17<>"","Cruce "&LOWER(AJ17)&" detectado en "&B17&" ("&D17&"). "&$E$5&" ha cruzado "&$E$6&" en 1 hora. Nivel: "&AK17&". "&TEXT(NOW(),"dd/mm/yyyy hh:mm"),"")))) | AM17: =IF(AL17="","",B17&"|"&IF(W17<>"","15min-VelaMA1",IF(X17<>"","15min-MA1MA2",IF(AI17<>"","1h-VelaMA1","1h-MA1MA2")))&"|"&TEXT(NOW(),"yyyymmddhhmm"))
A18: 7 | B18: Dolar NZ / Dolar | C18: =IFERROR(INDEX(Universo_Activos!$A$3:$A$1022,MATCH(B18,Universo_Activos!$C$3:$C$1022,0)),"") -> Forex | D18: =IFERROR(INDEX(Universo_Activos!$B$3:$B$1022,MATCH(B18,Universo_Activos!$C$3:$C$1022,0)),"") -> OTC/Interbancario | E18: =IFERROR(INDEX(Universo_Activos!$D$3:$D$1022,MATCH(B18,Universo_Activos!$C$3:$C$1022,0)),"") -> NZDUSD | F18: =IFERROR(INDEX(Universo_Activos!$E$3:$E$1022,MATCH(B18,Universo_Activos!$C$3:$C$1022,0)),"") -> N/A (par de divisas, sin ISIN) | G18: 216.27 | H18: 0.074 | I18: -0.0766 | J18: 0.0218 | K18: -0.0028 | L18: 0.0369 | M18: 0.59579 | N18: 0.59588 | O18: 0.59568129 | P18: 0.59565411 | Q18: 0.59586225 | R18: 0.59586986 | S18: 0.59630277 | T18: 0.5963237 | U18: 0.59658114 | V18: 0.59659176 | W18: =IF(AND(N18<=P18,M18>O18),"ALCISTA",IF(AND(N18>=P18,M18<O18),"BAJISTA","")) | X18: =IF(AND(P18<=R18,O18>Q18),"ALCISTA",IF(AND(P18>=R18,O18<Q18),"BAJISTA","")) | Y18: 0.59579 | Z18: 0.59535 | AA18: 0.59600828 | AB18: 0.59606284 | AC18: 0.5964673 | AD18: 0.5965386 | AE18: 0.59618862 | AF18: 0.59620489 | AG18: 0.5933538 | AH18: 0.5933211 | AI18: =IF(AND(Z18<=AB18,Y18>AA18),"ALCISTA",IF(AND(Z18>=AB18,Y18<AA18),"BAJISTA","")) | AJ18: =IF(AND(AB18<=AD18,AA18>AC18),"ALCISTA",IF(AND(AB18>=AD18,AA18<AC18),"BAJISTA","")) | AK18: =IF(W18<>"",IFERROR(INDEX(Niveles_Importancia!$A$3:$A$30,MATCH("Vela|"&$E$5&"|15 min",Niveles_Importancia!$H$3:$H$30,0)),"Sin clasificar"),IF(X18<>"",IFERROR(INDEX(Niveles_Importancia!$A$3:$A$30,MATCH($E$5&"|"&$E$6&"|15 min",Niveles_Importancia!$H$3:$H$30,0)),"Sin clasificar"),IF(AI18<>"",IFERROR(INDEX(Niveles_Importancia!$A$3:$A$30,MATCH("Vela|"&$E$5&"|1 hora",Niveles_Importancia!$H$3:$H$30,0)),"Sin clasificar"),IF(AJ18<>"",IFERROR(INDEX(Niveles_Importancia!$A$3:$A$30,MATCH($E$5&"|"&$E$6&"|1 hora",Niveles_Importancia!$H$3:$H$30,0)),"Sin clasificar"),"")))) | AL18: =IF(W18<>"","Cruce "&LOWER(W18)&" detectado en "&B18&" ("&D18&"). La vela ha cruzado "&$E$5&" en 15 min. Nivel: "&AK18&". Precio: "&TEXT(M18,"0.00")&". "&TEXT(NOW(),"dd/mm/yyyy hh:mm"),IF(X18<>"","Cruce "&LOWER(X18)&" detectado en "&B18&" ("&D18&"). "&$E$5&" ha cruzado "&$E$6&" en 15 min. Nivel: "&AK18&". "&TEXT(NOW(),"dd/mm/yyyy hh:mm"),IF(AI18<>"","Cruce "&LOWER(AI18)&" detectado en "&B18&" ("&D18&"). La vela ha cruzado "&$E$5&" en 1 hora. Nivel: "&AK18&". "&TEXT(NOW(),"dd/mm/yyyy hh:mm"),IF(AJ18<>"","Cruce "&LOWER(AJ18)&" detectado en "&B18&" ("&D18&"). "&$E$5&" ha cruzado "&$E$6&" en 1 hora. Nivel: "&AK18&". "&TEXT(NOW(),"dd/mm/yyyy hh:mm"),"")))) | AM18: =IF(AL18="","",B18&"|"&IF(W18<>"","15min-VelaMA1",IF(X18<>"","15min-MA1MA2",IF(AI18<>"","1h-VelaMA1","1h-MA1MA2")))&"|"&TEXT(NOW(),"yyyymmddhhmm"))
A19: 8 | B19: Euro / Libra | C19: =IFERROR(INDEX(Universo_Activos!$A$3:$A$1022,MATCH(B19,Universo_Activos!$C$3:$C$1022,0)),"") -> Forex | D19: =IFERROR(INDEX(Universo_Activos!$B$3:$B$1022,MATCH(B19,Universo_Activos!$C$3:$C$1022,0)),"") -> OTC/Interbancario | E19: =IFERROR(INDEX(Universo_Activos!$D$3:$D$1022,MATCH(B19,Universo_Activos!$C$3:$C$1022,0)),"") -> EURGBP | F19: =IFERROR(INDEX(Universo_Activos!$E$3:$E$1022,MATCH(B19,Universo_Activos!$C$3:$C$1022,0)),"") -> N/A (par de divisas, sin ISIN) | G19: 183.15 | H19: 0.0174 | I19: -0.0672 | J19: 0.0223 | K19: 0.0789 | L19: 0.0608 | M19: 0.85554 | N19: 0.85558 | O19: 0.85553931 | P19: 0.85553914 | Q19: 0.8555466 | R19: 0.85554729 | S19: 0.85563045 | T19: 0.85563414 | U19: 0.8560487 | V19: 0.85605553 | W19: =IF(AND(N19<=P19,M19>O19),"ALCISTA",IF(AND(N19>=P19,M19<O19),"BAJISTA","")) | X19: =IF(AND(P19<=R19,O19>Q19),"ALCISTA",IF(AND(P19>=R19,O19<Q19),"BAJISTA","")) -> ALCISTA | Y19: 0.85554 | Z19: 0.85549 | AA19: 0.85558319 | AB19: 0.85559399 | AC19: 0.85572966 | AD19: 0.85574963 | AE19: 0.85607013 | AF19: 0.85609177 | AG19: 0.8560306 | AH19: 0.85603719 | AI19: =IF(AND(Z19<=AB19,Y19>AA19),"ALCISTA",IF(AND(Z19>=AB19,Y19<AA19),"BAJISTA","")) -> ALCISTA | AJ19: =IF(AND(AB19<=AD19,AA19>AC19),"ALCISTA",IF(AND(AB19>=AD19,AA19<AC19),"BAJISTA","")) | AK19: =IF(W19<>"",IFERROR(INDEX(Niveles_Importancia!$A$3:$A$30,MATCH("Vela|"&$E$5&"|15 min",Niveles_Importancia!$H$3:$H$30,0)),"Sin clasificar"),IF(X19<>"",IFERROR(INDEX(Niveles_Importancia!$A$3:$A$30,MATCH($E$5&"|"&$E$6&"|15 min",Niveles_Importancia!$H$3:$H$30,0)),"Sin clasificar"),IF(AI19<>"",IFERROR(INDEX(Niveles_Importancia!$A$3:$A$30,MATCH("Vela|"&$E$5&"|1 hora",Niveles_Importancia!$H$3:$H$30,0)),"Sin clasificar"),IF(AJ19<>"",IFERROR(INDEX(Niveles_Importancia!$A$3:$A$30,MATCH($E$5&"|"&$E$6&"|1 hora",Niveles_Importancia!$H$3:$H$30,0)),"Sin clasificar"),"")))) -> 1 | AL19: =IF(W19<>"","Cruce "&LOWER(W19)&" detectado en "&B19&" ("&D19&"). La vela ha cruzado "&$E$5&" en 15 min. Nivel: "&AK19&". Precio: "&TEXT(M19,"0.00")&". "&TEXT(NOW(),"dd/mm/yyyy hh:mm"),IF(X19<>"","Cruce "&LOWER(X19)&" detectado en "&B19&" ("&D19&"). "&$E$5&" ha cruzado "&$E$6&" en 15 min. Nivel: "&AK19&". "&TEXT(NOW(),"dd/mm/yyyy hh:mm"),IF(AI19<>"","Cruce "&LOWER(AI19)&" detectado en "&B19&" ("&D19&"). La vela ha cruzado "&$E$5&" en 1 hora. Nivel: "&AK19&". "&TEXT(NOW(),"dd/mm/yyyy hh:mm"),IF(AJ19<>"","Cruce "&LOWER(AJ19)&" detectado en "&B19&" ("&D19&"). "&$E$5&" ha cruzado "&$E$6&" en 1 hora. Nivel: "&AK19&". "&TEXT(NOW(),"dd/mm/yyyy hh:mm"),"")))) -> Cruce alcista detectado en Euro / Libra (OTC/Interbancario). EMA 9 ha cruzado EMA 20 en 15 min. Nivel: 1. 31/07/yyyy 20:15 | AM19: =IF(AL19="","",B19&"|"&IF(W19<>"","15min-VelaMA1",IF(X19<>"","15min-MA1MA2",IF(AI19<>"","1h-VelaMA1","1h-MA1MA2")))&"|"&TEXT(NOW(),"yyyymmddhhmm")) -> Euro / Libra|15min-MA1MA2|yyyy07312015
A20: 9 | B20: Banco Santander | C20: =IFERROR(INDEX(Universo_Activos!$A$3:$A$1022,MATCH(B20,Universo_Activos!$C$3:$C$1022,0)),"") -> Acciones Espana | D20: =IFERROR(INDEX(Universo_Activos!$B$3:$B$1022,MATCH(B20,Universo_Activos!$C$3:$C$1022,0)),"") -> BME (Madrid) | E20: =IFERROR(INDEX(Universo_Activos!$D$3:$D$1022,MATCH(B20,Universo_Activos!$C$3:$C$1022,0)),"") -> SAN.MC | F20: =IFERROR(INDEX(Universo_Activos!$E$3:$E$1022,MATCH(B20,Universo_Activos!$C$3:$C$1022,0)),"") -> ES0113900J37 | G20: 76.72 | H20: -0.0529 | I20: 0.0649 | J20: 0.0256 | K20: -0.0093 | L20: 0.0627 | M20: 12.702 | N20: 12.742 | O20: 12.703929 | P20: 12.704411 | Q20: 12.676116 | R20: 12.673392 | S20: 12.60757 | T20: 12.603716 | U20: 12.551894 | V20: 12.549879 | W20: =IF(AND(N20<=P20,M20>O20),"ALCISTA",IF(AND(N20>=P20,M20<O20),"BAJISTA","")) -> ALCISTA | X20: =IF(AND(P20<=R20,O20>Q20),"ALCISTA",IF(AND(P20>=R20,O20<Q20),"BAJISTA","")) | Y20: 12.702 | Z20: 12.708 | AA20: 12.645177 | AB20: 12.630971 | AC20: 12.569498 | AD20: 12.55555 | AE20: 12.558846 | AF20: 12.553003 | AG20: 12.561982 | AH20: 12.560102 | AI20: =IF(AND(Z20<=AB20,Y20>AA20),"ALCISTA",IF(AND(Z20>=AB20,Y20<AA20),"BAJISTA","")) | AJ20: =IF(AND(AB20<=AD20,AA20>AC20),"ALCISTA",IF(AND(AB20>=AD20,AA20<AC20),"BAJISTA","")) | AK20: =IF(W20<>"",IFERROR(INDEX(Niveles_Importancia!$A$3:$A$30,MATCH("Vela|"&$E$5&"|15 min",Niveles_Importancia!$H$3:$H$30,0)),"Sin clasificar"),IF(X20<>"",IFERROR(INDEX(Niveles_Importancia!$A$3:$A$30,MATCH($E$5&"|"&$E$6&"|15 min",Niveles_Importancia!$H$3:$H$30,0)),"Sin clasificar"),IF(AI20<>"",IFERROR(INDEX(Niveles_Importancia!$A$3:$A$30,MATCH("Vela|"&$E$5&"|1 hora",Niveles_Importancia!$H$3:$H$30,0)),"Sin clasificar"),IF(AJ20<>"",IFERROR(INDEX(Niveles_Importancia!$A$3:$A$30,MATCH($E$5&"|"&$E$6&"|1 hora",Niveles_Importancia!$H$3:$H$30,0)),"Sin clasificar"),"")))) -> Sin clasificar | AL20: =IF(W20<>"","Cruce "&LOWER(W20)&" detectado en "&B20&" ("&D20&"). La vela ha cruzado "&$E$5&" en 15 min. Nivel: "&AK20&". Precio: "&TEXT(M20,"0.00")&". "&TEXT(NOW(),"dd/mm/yyyy hh:mm"),IF(X20<>"","Cruce "&LOWER(X20)&" detectado en "&B20&" ("&D20&"). "&$E$5&" ha cruzado "&$E$6&" en 15 min. Nivel: "&AK20&". "&TEXT(NOW(),"dd/mm/yyyy hh:mm"),IF(AI20<>"","Cruce "&LOWER(AI20)&" detectado en "&B20&" ("&D20&"). La vela ha cruzado "&$E$5&" en 1 hora. Nivel: "&AK20&". "&TEXT(NOW(),"dd/mm/yyyy hh:mm"),IF(AJ20<>"","Cruce "&LOWER(AJ20)&" detectado en "&B20&" ("&D20&"). "&$E$5&" ha cruzado "&$E$6&" en 1 hora. Nivel: "&AK20&". "&TEXT(NOW(),"dd/mm/yyyy hh:mm"),"")))) -> Cruce alcista detectado en Banco Santander (BME (Madrid)). La vela ha cruzado EMA 9 en 15 min. Nivel: Sin clasificar. Precio: 012. 31/07/yyyy 20:15 | AM20: =IF(AL20="","",B20&"|"&IF(W20<>"","15min-VelaMA1",IF(X20<>"","15min-MA1MA2",IF(AI20<>"","1h-VelaMA1","1h-MA1MA2")))&"|"&TEXT(NOW(),"yyyymmddhhmm")) -> Banco Santander|15min-VelaMA1|yyyy07312015
A21: 10 | B21: BBVA | C21: =IFERROR(INDEX(Universo_Activos!$A$3:$A$1022,MATCH(B21,Universo_Activos!$C$3:$C$1022,0)),"") -> Acciones Espana | D21: =IFERROR(INDEX(Universo_Activos!$B$3:$B$1022,MATCH(B21,Universo_Activos!$C$3:$C$1022,0)),"") -> BME (Madrid) | E21: =IFERROR(INDEX(Universo_Activos!$D$3:$D$1022,MATCH(B21,Universo_Activos!$C$3:$C$1022,0)),"") -> BBVA.MC | F21: =IFERROR(INDEX(Universo_Activos!$E$3:$E$1022,MATCH(B21,Universo_Activos!$C$3:$C$1022,0)),"") -> ES0113211835 | G21: 79.94 | H21: -0.0138 | I21: 0.0201 | J21: -0.001 | K21: -0.0295 | L21: 0.0543 | M21: 25.07 | N21: 25.14 | O21: 25.060737 | P21: 25.058421 | Q21: 24.999477 | R21: 24.992054 | S21: 24.90161 | T21: 24.894737 | U21: 24.83687 | V21: 24.833741 | W21: =IF(AND(N21<=P21,M21>O21),"ALCISTA",IF(AND(N21>=P21,M21<O21),"BAJISTA","")) | X21: =IF(AND(P21<=R21,O21>Q21),"ALCISTA",IF(AND(P21>=R21,O21<Q21),"BAJISTA","")) | Y21: 25.07 | Z21: 25.08 | AA21: 24.954599 | AB21: 24.925749 | AC21: 24.866246 | AD21: 24.844798 | AE21: 24.830071 | AF21: 24.820277 | AG21: 24.521791 | AH21: 24.514432 | AI21: =IF(AND(Z21<=AB21,Y21>AA21),"ALCISTA",IF(AND(Z21>=AB21,Y21<AA21),"BAJISTA","")) | AJ21: =IF(AND(AB21<=AD21,AA21>AC21),"ALCISTA",IF(AND(AB21>=AD21,AA21<AC21),"BAJISTA","")) | AK21: =IF(W21<>"",IFERROR(INDEX(Niveles_Importancia!$A$3:$A$30,MATCH("Vela|"&$E$5&"|15 min",Niveles_Importancia!$H$3:$H$30,0)),"Sin clasificar"),IF(X21<>"",IFERROR(INDEX(Niveles_Importancia!$A$3:$A$30,MATCH($E$5&"|"&$E$6&"|15 min",Niveles_Importancia!$H$3:$H$30,0)),"Sin clasificar"),IF(AI21<>"",IFERROR(INDEX(Niveles_Importancia!$A$3:$A$30,MATCH("Vela|"&$E$5&"|1 hora",Niveles_Importancia!$H$3:$H$30,0)),"Sin clasificar"),IF(AJ21<>"",IFERROR(INDEX(Niveles_Importancia!$A$3:$A$30,MATCH($E$5&"|"&$E$6&"|1 hora",Niveles_Importancia!$H$3:$H$30,0)),"Sin clasificar"),"")))) | AL21: =IF(W21<>"","Cruce "&LOWER(W21)&" detectado en "&B21&" ("&D21&"). La vela ha cruzado "&$E$5&" en 15 min. Nivel: "&AK21&". Precio: "&TEXT(M21,"0.00")&". "&TEXT(NOW(),"dd/mm/yyyy hh:mm"),IF(X21<>"","Cruce "&LOWER(X21)&" detectado en "&B21&" ("&D21&"). "&$E$5&" ha cruzado "&$E$6&" en 15 min. Nivel: "&AK21&". "&TEXT(NOW(),"dd/mm/yyyy hh:mm"),IF(AI21<>"","Cruce "&LOWER(AI21)&" detectado en "&B21&" ("&D21&"). La vela ha cruzado "&$E$5&" en 1 hora. Nivel: "&AK21&". "&TEXT(NOW(),"dd/mm/yyyy hh:mm"),IF(AJ21<>"","Cruce "&LOWER(AJ21)&" detectado en "&B21&" ("&D21&"). "&$E$5&" ha cruzado "&$E$6&" en 1 hora. Nivel: "&AK21&". "&TEXT(NOW(),"dd/mm/yyyy hh:mm"),"")))) | AM21: =IF(AL21="","",B21&"|"&IF(W21<>"","15min-VelaMA1",IF(X21<>"","15min-MA1MA2",IF(AI21<>"","1h-VelaMA1","1h-MA1MA2")))&"|"&TEXT(NOW(),"yyyymmddhhmm"))
A22: 11 | B22: Iberdrola | C22: =IFERROR(INDEX(Universo_Activos!$A$3:$A$1022,MATCH(B22,Universo_Activos!$C$3:$C$1022,0)),"") -> Acciones Espana | D22: =IFERROR(INDEX(Universo_Activos!$B$3:$B$1022,MATCH(B22,Universo_Activos!$C$3:$C$1022,0)),"") -> BME (Madrid) | E22: =IFERROR(INDEX(Universo_Activos!$D$3:$D$1022,MATCH(B22,Universo_Activos!$C$3:$C$1022,0)),"") -> IBE.MC | F22: =IFERROR(INDEX(Universo_Activos!$E$3:$E$1022,MATCH(B22,Universo_Activos!$C$3:$C$1022,0)),"") -> ES0144580Y14 | G22: 196.39 | H22: 0.0248 | I22: 0.0492 | J22: 0.0734 | K22: 0.0295 | L22: -0.0481 | M22: 20.03 | N22: 20.01 | O22: 19.995626 | P22: 19.987032 | Q22: 19.994422 | R22: 19.990677 | S22: 20.026701 | T22: 20.026566 | U22: 20.099314 | V22: 20.100244 | W22: =IF(AND(N22<=P22,M22>O22),"ALCISTA",IF(AND(N22>=P22,M22<O22),"BAJISTA","")) | X22: =IF(AND(P22<=R22,O22>Q22),"ALCISTA",IF(AND(P22>=R22,O22<Q22),"BAJISTA","")) | Y22: 20.03 | Z22: 19.985 | AA22: 20.015267 | AB22: 20.011583 | AC22: 20.049488 | AD22: 20.05154 | AE22: 20.127889 | AF22: 20.131884 | AG22: 20.393253 | AH22: 20.398129 | AI22: =IF(AND(Z22<=AB22,Y22>AA22),"ALCISTA",IF(AND(Z22>=AB22,Y22<AA22),"BAJISTA","")) | AJ22: =IF(AND(AB22<=AD22,AA22>AC22),"ALCISTA",IF(AND(AB22>=AD22,AA22<AC22),"BAJISTA","")) | AK22: =IF(W22<>"",IFERROR(INDEX(Niveles_Importancia!$A$3:$A$30,MATCH("Vela|"&$E$5&"|15 min",Niveles_Importancia!$H$3:$H$30,0)),"Sin clasificar"),IF(X22<>"",IFERROR(INDEX(Niveles_Importancia!$A$3:$A$30,MATCH($E$5&"|"&$E$6&"|15 min",Niveles_Importancia!$H$3:$H$30,0)),"Sin clasificar"),IF(AI22<>"",IFERROR(INDEX(Niveles_Importancia!$A$3:$A$30,MATCH("Vela|"&$E$5&"|1 hora",Niveles_Importancia!$H$3:$H$30,0)),"Sin clasificar"),IF(AJ22<>"",IFERROR(INDEX(Niveles_Importancia!$A$3:$A$30,MATCH($E$5&"|"&$E$6&"|1 hora",Niveles_Importancia!$H$3:$H$30,0)),"Sin clasificar"),"")))) | AL22: =IF(W22<>"","Cruce "&LOWER(W22)&" detectado en "&B22&" ("&D22&"). La vela ha cruzado "&$E$5&" en 15 min. Nivel: "&AK22&". Precio: "&TEXT(M22,"0.00")&". "&TEXT(NOW(),"dd/mm/yyyy hh:mm"),IF(X22<>"","Cruce "&LOWER(X22)&" detectado en "&B22&" ("&D22&"). "&$E$5&" ha cruzado "&$E$6&" en 15 min. Nivel: "&AK22&". "&TEXT(NOW(),"dd/mm/yyyy hh:mm"),IF(AI22<>"","Cruce "&LOWER(AI22)&" detectado en "&B22&" ("&D22&"). La vela ha cruzado "&$E$5&" en 1 hora. Nivel: "&AK22&". "&TEXT(NOW(),"dd/mm/yyyy hh:mm"),IF(AJ22<>"","Cruce "&LOWER(AJ22)&" detectado en "&B22&" ("&D22&"). "&$E$5&" ha cruzado "&$E$6&" en 1 hora. Nivel: "&AK22&". "&TEXT(NOW(),"dd/mm/yyyy hh:mm"),"")))) | AM22: =IF(AL22="","",B22&"|"&IF(W22<>"","15min-VelaMA1",IF(X22<>"","15min-MA1MA2",IF(AI22<>"","1h-VelaMA1","1h-MA1MA2")))&"|"&TEXT(NOW(),"yyyymmddhhmm"))
A23: 12 | B23: Inditex | C23: =IFERROR(INDEX(Universo_Activos!$A$3:$A$1022,MATCH(B23,Universo_Activos!$C$3:$C$1022,0)),"") -> Acciones Espana | D23: =IFERROR(INDEX(Universo_Activos!$B$3:$B$1022,MATCH(B23,Universo_Activos!$C$3:$C$1022,0)),"") -> BME (Madrid) | E23: =IFERROR(INDEX(Universo_Activos!$D$3:$D$1022,MATCH(B23,Universo_Activos!$C$3:$C$1022,0)),"") -> ITX.MC | F23: =IFERROR(INDEX(Universo_Activos!$E$3:$E$1022,MATCH(B23,Universo_Activos!$C$3:$C$1022,0)),"") -> ES0148396007 | G23: 195.15 | H23: 0.0656 | I23: -0.0197 | J23: 0.011 | K23: 0.0607 | L23: 0.0475 | M23: 58.42 | N23: 58.52 | O23: 58.515202 | P23: 58.539002 | Q23: 58.494253 | R23: 58.502069 | S23: 58.332386 | T23: 58.32881 | U23: 58.031176 | V23: 58.025956 | W23: =IF(AND(N23<=P23,M23>O23),"ALCISTA",IF(AND(N23>=P23,M23<O23),"BAJISTA","")) | X23: =IF(AND(P23<=R23,O23>Q23),"ALCISTA",IF(AND(P23>=R23,O23<Q23),"BAJISTA","")) | Y23: 58.42 | Z23: 58.56 | AA23: 58.43981 | AB23: 58.444762 | AC23: 58.231285 | AD23: 58.21142 | AE23: 57.97861 | AF23: 57.960594 | AG23: 57.547444 | AH23: 57.535732 | AI23: =IF(AND(Z23<=AB23,Y23>AA23),"ALCISTA",IF(AND(Z23>=AB23,Y23<AA23),"BAJISTA","")) | AJ23: =IF(AND(AB23<=AD23,AA23>AC23),"ALCISTA",IF(AND(AB23>=AD23,AA23<AC23),"BAJISTA","")) | AK23: =IF(W23<>"",IFERROR(INDEX(Niveles_Importancia!$A$3:$A$30,MATCH("Vela|"&$E$5&"|15 min",Niveles_Importancia!$H$3:$H$30,0)),"Sin clasificar"),IF(X23<>"",IFERROR(INDEX(Niveles_Importancia!$A$3:$A$30,MATCH($E$5&"|"&$E$6&"|15 min",Niveles_Importancia!$H$3:$H$30,0)),"Sin clasificar"),IF(AI23<>"",IFERROR(INDEX(Niveles_Importancia!$A$3:$A$30,MATCH("Vela|"&$E$5&"|1 hora",Niveles_Importancia!$H$3:$H$30,0)),"Sin clasificar"),IF(AJ23<>"",IFERROR(INDEX(Niveles_Importancia!$A$3:$A$30,MATCH($E$5&"|"&$E$6&"|1 hora",Niveles_Importancia!$H$3:$H$30,0)),"Sin clasificar"),"")))) | AL23: =IF(W23<>"","Cruce "&LOWER(W23)&" detectado en "&B23&" ("&D23&"). La vela ha cruzado "&$E$5&" en 15 min. Nivel: "&AK23&". Precio: "&TEXT(M23,"0.00")&". "&TEXT(NOW(),"dd/mm/yyyy hh:mm"),IF(X23<>"","Cruce "&LOWER(X23)&" detectado en "&B23&" ("&D23&"). "&$E$5&" ha cruzado "&$E$6&" en 15 min. Nivel: "&AK23&". "&TEXT(NOW(),"dd/mm/yyyy hh:mm"),IF(AI23<>"","Cruce "&LOWER(AI23)&" detectado en "&B23&" ("&D23&"). La vela ha cruzado "&$E$5&" en 1 hora. Nivel: "&AK23&". "&TEXT(NOW(),"dd/mm/yyyy hh:mm"),IF(AJ23<>"","Cruce "&LOWER(AJ23)&" detectado en "&B23&" ("&D23&"). "&$E$5&" ha cruzado "&$E$6&" en 1 hora. Nivel: "&AK23&". "&TEXT(NOW(),"dd/mm/yyyy hh:mm"),"")))) | AM23: =IF(AL23="","",B23&"|"&IF(W23<>"","15min-VelaMA1",IF(X23<>"","15min-MA1MA2",IF(AI23<>"","1h-VelaMA1","1h-MA1MA2")))&"|"&TEXT(NOW(),"yyyymmddhhmm"))
... A111: 100 | B111: Adyen | C111: =IFERROR(INDEX(Universo_Activos!$A$3:$A$1022,MATCH(B111,Universo_Activos!$C$3:$C$1022,0)),"") -> Acciones Europa | D111: =IFERROR(INDEX(Universo_Activos!$B$3:$B$1022,MATCH(B111,Universo_Activos!$C$3:$C$1022,0)),"") -> Euronext Amsterdam | E111: =IFERROR(INDEX(Universo_Activos!$D$3:$D$1022,MATCH(B111,Universo_Activos!$C$3:$C$1022,0)),"") -> EURONEXT:ADYEN | F111: =IFERROR(INDEX(Universo_Activos!$E$3:$E$1022,MATCH(B111,Universo_Activos!$C$3:$C$1022,0)),"") -> NL0012969182 | G111: 287.92 | H111: 0.0677 | I111: -0.0369 | J111: -0.0043 | K111: -0.0597 | L111: -0.0106 | M111: 58.545 | N111: 58.42 | O111: 58.173723 | P111: 58.080903 | Q111: 57.875812 | R111: 57.805371 | S111: 57.745876 | T111: 57.713258 | U111: 57.854694 | V111: 57.845428 | W111: =IF(AND(N111<=P111,M111>O111),"ALCISTA",IF(AND(N111>=P111,M111<O111),"BAJISTA","")) | X111: =IF(AND(P111<=R111,O111>Q111),"ALCISTA",IF(AND(P111>=R111,O111<Q111),"BAJISTA","")) | Y111: 58.545 | Z111: 58.155 | AA111: 57.876309 | AB111: 57.709136 | AC111: 57.784762 | AD111: 57.704737 | AE111: 57.924562 | AF111: 57.899238 | AG111: 58.256414 | AH111: 58.252541 | AI111: =IF(AND(Z111<=AB111,Y111>AA111),"ALCISTA",IF(AND(Z111>=AB111,Y111<AA111),"BAJISTA","")) | AJ111: =IF(AND(AB111<=AD111,AA111>AC111),"ALCISTA",IF(AND(AB111>=AD111,AA111<AC111),"BAJISTA","")) | AK111: =IF(W111<>"",IFERROR(INDEX(Niveles_Importancia!$A$3:$A$30,MATCH("Vela|"&$E$5&"|15 min",Niveles_Importancia!$H$3:$H$30,0)),"Sin clasificar"),IF(X111<>"",IFERROR(INDEX(Niveles_Importancia!$A$3:$A$30,MATCH($E$5&"|"&$E$6&"|15 min",Niveles_Importancia!$H$3:$H$30,0)),"Sin clasificar"),IF(AI111<>"",IFERROR(INDEX(Niveles_Importancia!$A$3:$A$30,MATCH("Vela|"&$E$5&"|1 hora",Niveles_Importancia!$H$3:$H$30,0)),"Sin clasificar"),IF(AJ111<>"",IFERROR(INDEX(Niveles_Importancia!$A$3:$A$30,MATCH($E$5&"|"&$E$6&"|1 hora",Niveles_Importancia!$H$3:$H$30,0)),"Sin clasificar"),"")))) | AL111: =IF(W111<>"","Cruce "&LOWER(W111)&" detectado en "&B111&" ("&D111&"). La vela ha cruzado "&$E$5&" en 15 min. Nivel: "&AK111&". Precio: "&TEXT(M111,"0.00")&". "&TEXT(NOW(),"dd/mm/yyyy hh:mm"),IF(X111<>"","Cruce "&LOWER(X111)&" detectado en "&B111&" ("&D111&"). "&$E$5&" ha cruzado "&$E$6&" en 15 min. Nivel: "&AK111&". "&TEXT(NOW(),"dd/mm/yyyy hh:mm"),IF(AI111<>"","Cruce "&LOWER(AI111)&" detectado en "&B111&" ("&D111&"). La vela ha cruzado "&$E$5&" en 1 hora. Nivel: "&AK111&". "&TEXT(NOW(),"dd/mm/yyyy hh:mm"),IF(AJ111<>"","Cruce "&LOWER(AJ111)&" detectado en "&B111&" ("&D111&"). "&$E$5&" ha cruzado "&$E$6&" en 1 hora. Nivel: "&AK111&". "&TEXT(NOW(),"dd/mm/yyyy hh:mm"),"")))) | AM111: =IF(AL111="","",B111&"|"&IF(W111<>"","15min-VelaMA1",IF(X111<>"","15min-MA1MA2",IF(AI111<>"","1h-VelaMA1","1h-MA1MA2")))&"|"&TEXT(NOW(),"yyyymmddhhmm"))
B114: Fecha/Hora | C114: Activo | D114: Mercado | E114: Time Frame | F114: Tipo de cruce | G114: Direccion | H114: Nivel | I114: Mensaje
B115: =IF($AL12="","",TEXT(NOW(),"dd/mm/yyyy hh:mm")) | C115: =IF($AL12="","",$B12) | D115: =IF($AL12="","",$D12) | E115: =IF($AL12="","",IF($W12<>"","15 min",IF($X12<>"","15 min",IF($AI12<>"","1 hora","1 hora")))) | F115: =IF($AL12="","",IF($W12<>"","Vela/Media",IF($X12<>"","Media/Media",IF($AI12<>"","Vela/Media","Media/Media")))) | G115: =IF($AL12="","",IF($W12<>"",$W12,IF($X12<>"",$X12,IF($AI12<>"",$AI12,$AJ12)))) | H115: =IF($AL12="","",$AK12) | I115: =$AL12
B116: =IF($AL13="","",TEXT(NOW(),"dd/mm/yyyy hh:mm")) | C116: =IF($AL13="","",$B13) | D116: =IF($AL13="","",$D13) | E116: =IF($AL13="","",IF($W13<>"","15 min",IF($X13<>"","15 min",IF($AI13<>"","1 hora","1 hora")))) | F116: =IF($AL13="","",IF($W13<>"","Vela/Media",IF($X13<>"","Media/Media",IF($AI13<>"","Vela/Media","Media/Media")))) | G116: =IF($AL13="","",IF($W13<>"",$W13,IF($X13<>"",$X13,IF($AI13<>"",$AI13,$AJ13)))) | H116: =IF($AL13="","",$AK13) | I116: =$AL13
B117: =IF($AL14="","",TEXT(NOW(),"dd/mm/yyyy hh:mm")) | C117: =IF($AL14="","",$B14) | D117: =IF($AL14="","",$D14) | E117: =IF($AL14="","",IF($W14<>"","15 min",IF($X14<>"","15 min",IF($AI14<>"","1 hora","1 hora")))) | F117: =IF($AL14="","",IF($W14<>"","Vela/Media",IF($X14<>"","Media/Media",IF($AI14<>"","Vela/Media","Media/Media")))) | G117: =IF($AL14="","",IF($W14<>"",$W14,IF($X14<>"",$X14,IF($AI14<>"",$AI14,$AJ14)))) | H117: =IF($AL14="","",$AK14) | I117: =$AL14
B118: =IF($AL15="","",TEXT(NOW(),"dd/mm/yyyy hh:mm")) | C118: =IF($AL15="","",$B15) | D118: =IF($AL15="","",$D15) | E118: =IF($AL15="","",IF($W15<>"","15 min",IF($X15<>"","15 min",IF($AI15<>"","1 hora","1 hora")))) | F118: =IF($AL15="","",IF($W15<>"","Vela/Media",IF($X15<>"","Media/Media",IF($AI15<>"","Vela/Media","Media/Media")))) | G118: =IF($AL15="","",IF($W15<>"",$W15,IF($X15<>"",$X15,IF($AI15<>"",$AI15,$AJ15)))) | H118: =IF($AL15="","",$AK15) | I118: =$AL15
B119: =IF($AL16="","",TEXT(NOW(),"dd/mm/yyyy hh:mm")) | C119: =IF($AL16="","",$B16) | D119: =IF($AL16="","",$D16) | E119: =IF($AL16="","",IF($W16<>"","15 min",IF($X16<>"","15 min",IF($AI16<>"","1 hora","1 hora")))) | F119: =IF($AL16="","",IF($W16<>"","Vela/Media",IF($X16<>"","Media/Media",IF($AI16<>"","Vela/Media","Media/Media")))) | G119: =IF($AL16="","",IF($W16<>"",$W16,IF($X16<>"",$X16,IF($AI16<>"",$AI16,$AJ16)))) | H119: =IF($AL16="","",$AK16) | I119: =$AL16
B120: =IF($AL17="","",TEXT(NOW(),"dd/mm/yyyy hh:mm")) | C120: =IF($AL17="","",$B17) | D120: =IF($AL17="","",$D17) | E120: =IF($AL17="","",IF($W17<>"","15 min",IF($X17<>"","15 min",IF($AI17<>"","1 hora","1 hora")))) | F120: =IF($AL17="","",IF($W17<>"","Vela/Media",IF($X17<>"","Media/Media",IF($AI17<>"","Vela/Media","Media/Media")))) | G120: =IF($AL17="","",IF($W17<>"",$W17,IF($X17<>"",$X17,IF($AI17<>"",$AI17,$AJ17)))) | H120: =IF($AL17="","",$AK17) | I120: =$AL17
B121: =IF($AL18="","",TEXT(NOW(),"dd/mm/yyyy hh:mm")) | C121: =IF($AL18="","",$B18) | D121: =IF($AL18="","",$D18) | E121: =IF($AL18="","",IF($W18<>"","15 min",IF($X18<>"","15 min",IF($AI18<>"","1 hora","1 hora")))) | F121: =IF($AL18="","",IF($W18<>"","Vela/Media",IF($X18<>"","Media/Media",IF($AI18<>"","Vela/Media","Media/Media")))) | G121: =IF($AL18="","",IF($W18<>"",$W18,IF($X18<>"",$X18,IF($AI18<>"",$AI18,$AJ18)))) | H121: =IF($AL18="","",$AK18) | I121: =$AL18
B122: =IF($AL19="","",TEXT(NOW(),"dd/mm/yyyy hh:mm")) -> 31/07/yyyy 20:15 | C122: =IF($AL19="","",$B19) -> Euro / Libra | D122: =IF($AL19="","",$D19) -> OTC/Interbancario | E122: =IF($AL19="","",IF($W19<>"","15 min",IF($X19<>"","15 min",IF($AI19<>"","1 hora","1 hora")))) -> 15 min | F122: =IF($AL19="","",IF($W19<>"","Vela/Media",IF($X19<>"","Media/Media",IF($AI19<>"","Vela/Media","Media/Media")))) -> Media/Media | G122: =IF($AL19="","",IF($W19<>"",$W19,IF($X19<>"",$X19,IF($AI19<>"",$AI19,$AJ19)))) -> ALCISTA | H122: =IF($AL19="","",$AK19) -> 1 | I122: =$AL19 -> Cruce alcista detectado en Euro / Libra (OTC/Interbancario). EMA 9 ha cruzado EMA 20 en 15 min. Nivel: 1. 31/07/yyyy 20:15
B123: =IF($AL20="","",TEXT(NOW(),"dd/mm/yyyy hh:mm")) -> 31/07/yyyy 20:15 | C123: =IF($AL20="","",$B20) -> Banco Santander | D123: =IF($AL20="","",$D20) -> BME (Madrid) | E123: =IF($AL20="","",IF($W20<>"","15 min",IF($X20<>"","15 min",IF($AI20<>"","1 hora","1 hora")))) -> 15 min | F123: =IF($AL20="","",IF($W20<>"","Vela/Media",IF($X20<>"","Media/Media",IF($AI20<>"","Vela/Media","Media/Media")))) -> Vela/Media | G123: =IF($AL20="","",IF($W20<>"",$W20,IF($X20<>"",$X20,IF($AI20<>"",$AI20,$AJ20)))) -> ALCISTA | H123: =IF($AL20="","",$AK20) -> Sin clasificar | I123: =$AL20 -> Cruce alcista detectado en Banco Santander (BME (Madrid)). La vela ha cruzado EMA 9 en 15 min. Nivel: Sin clasificar. Precio: 012. 31/07/yyyy 20:15
B124: =IF($AL21="","",TEXT(NOW(),"dd/mm/yyyy hh:mm")) | C124: =IF($AL21="","",$B21) | D124: =IF($AL21="","",$D21) | E124: =IF($AL21="","",IF($W21<>"","15 min",IF($X21<>"","15 min",IF($AI21<>"","1 hora","1 hora")))) | F124: =IF($AL21="","",IF($W21<>"","Vela/Media",IF($X21<>"","Media/Media",IF($AI21<>"","Vela/Media","Media/Media")))) | G124: =IF($AL21="","",IF($W21<>"",$W21,IF($X21<>"",$X21,IF($AI21<>"",$AI21,$AJ21)))) | H124: =IF($AL21="","",$AK21) | I124: =$AL21
B125: =IF($AL22="","",TEXT(NOW(),"dd/mm/yyyy hh:mm")) | C125: =IF($AL22="","",$B22) | D125: =IF($AL22="","",$D22) | E125: =IF($AL22="","",IF($W22<>"","15 min",IF($X22<>"","15 min",IF($AI22<>"","1 hora","1 hora")))) | F125: =IF($AL22="","",IF($W22<>"","Vela/Media",IF($X22<>"","Media/Media",IF($AI22<>"","Vela/Media","Media/Media")))) | G125: =IF($AL22="","",IF($W22<>"",$W22,IF($X22<>"",$X22,IF($AI22<>"",$AI22,$AJ22)))) | H125: =IF($AL22="","",$AK22) | I125: =$AL22
B126: =IF($AL23="","",TEXT(NOW(),"dd/mm/yyyy hh:mm")) | C126: =IF($AL23="","",$B23) | D126: =IF($AL23="","",$D23) | E126: =IF($AL23="","",IF($W23<>"","15 min",IF($X23<>"","15 min",IF($AI23<>"","1 hora","1 hora")))) | F126: =IF($AL23="","",IF($W23<>"","Vela/Media",IF($X23<>"","Media/Media",IF($AI23<>"","Vela/Media","Media/Media")))) | G126: =IF($AL23="","",IF($W23<>"",$W23,IF($X23<>"",$X23,IF($AI23<>"",$AI23,$AJ23)))) | H126: =IF($AL23="","",$AK23) | I126: =$AL23
B127: =IF($AL24="","",TEXT(NOW(),"dd/mm/yyyy hh:mm")) -> 31/07/yyyy 20:15 | C127: =IF($AL24="","",$B24) -> Telefónica | D127: =IF($AL24="","",$D24) -> BME (Madrid) | E127: =IF($AL24="","",IF($W24<>"","15 min",IF($X24<>"","15 min",IF($AI24<>"","1 hora","1 hora")))) -> 1 hora | F127: =IF($AL24="","",IF($W24<>"","Vela/Media",IF($X24<>"","Media/Media",IF($AI24<>"","Vela/Media","Media/Media")))) -> Vela/Media | G127: =IF($AL24="","",IF($W24<>"",$W24,IF($X24<>"",$X24,IF($AI24<>"",$AI24,$AJ24)))) -> ALCISTA | H127: =IF($AL24="","",$AK24) -> Sin clasificar | I127: =$AL24 -> Cruce alcista detectado en Telefónica (BME (Madrid)). La vela ha cruzado EMA 9 en 1 hora. Nivel: Sin clasificar. 31/07/yyyy 20:15
B128: =IF($AL26="","",TEXT(NOW(),"dd/mm/yyyy hh:mm")) -> 31/07/yyyy 20:15 | C128: =IF($AL26="","",$B26) -> CaixaBank | D128: =IF($AL26="","",$D26) -> BME (Madrid) | E128: =IF($AL26="","",IF($W26<>"","15 min",IF($X26<>"","15 min",IF($AI26<>"","1 hora","1 hora")))) -> 1 hora | F128: =IF($AL26="","",IF($W26<>"","Vela/Media",IF($X26<>"","Media/Media",IF($AI26<>"","Vela/Media","Media/Media")))) -> Media/Media | G128: =IF($AL26="","",IF($W26<>"",$W26,IF($X26<>"",$X26,IF($AI26<>"",$AI26,$AJ26)))) -> ALCISTA | H128: =IF($AL26="","",$AK26) -> 1 | I128: =$AL26 -> Cruce alcista detectado en CaixaBank (BME (Madrid)). EMA 9 ha cruzado EMA 20 en 1 hora. Nivel: 1. 31/07/yyyy 20:15
B129: =IF($AL111="","",TEXT(NOW(),"dd/mm/yyyy hh:mm")) | C129: =IF($AL111="","",$B111) | D129: =IF($AL111="","",$D111) | E129: =IF($AL111="","",IF($W111<>"","15 min",IF($X111<>"","15 min",IF($AI111<>"","1 hora","1 hora")))) | F129: =IF($AL111="","",IF($W111<>"","Vela/Media",IF($X111<>"","Media/Media",IF($AI111<>"","Vela/Media","Media/Media")))) | G129: =IF($AL111="","",IF($W111<>"",$W111,IF($X111<>"",$X111,IF($AI111<>"",$AI111,$AJ111)))) | H129: =IF($AL111="","",$AK111) | I129: =$AL111

Sheet Niveles_Importancia
A1: Define aquí las reglas de importancia. Si un cruce no coincide con ninguna regla → 'Sin clasificar'.
A2: Nivel | B2: Tipo Elemento 1 | C2: Elemento 1 | D2: Tipo Elemento 2 | E2: Elemento 2 | F2: Time Frame | G2: Descripción | H2: Clave (uso interno)
A3: 1 | B3: Media móvil | C3: EMA 9 | D3: Media móvil | E3: EMA 20 | F3: 15 min | G3: Nivel 1: EMA 9 cruza EMA 20 en 15 min | H3: EMA 9|EMA 20|15 min
A4: 1 | B4: Media móvil | C4: EMA 9 | D4: Media móvil | E4: EMA 20 | F4: 1 hora | G4: Nivel 1: EMA 9 cruza EMA 20 en 1 hora | H4: EMA 9|EMA 20|1 hora
A5: 1 | B5: Media móvil | C5: EMA 9 | D5: Media móvil | E5: EMA 20 | F5: 4 horas | G5: Nivel 1: EMA 9 cruza EMA 20 en 4 horas | H5: EMA 9|EMA 20|4 horas
A6: 2 | B6: Media móvil | C6: EMA 9 | D6: Media móvil | E6: EMA 50 | F6: 15 min | G6: Nivel 2: EMA 9 cruza EMA 50 en 15 min | H6: EMA 9|EMA 50|15 min
A7: 2 | B7: Media móvil | C7: EMA 9 | D7: Media móvil | E7: EMA 50 | F7: 1 hora | G7: Nivel 2: EMA 9 cruza EMA 50 en 1 hora | H7: EMA 9|EMA 50|1 hora
A8: 2 | B8: Media móvil | C8: EMA 9 | D8: Media móvil | E8: EMA 50 | F8: 4 horas | G8: Nivel 2: EMA 9 cruza EMA 50 en 4 horas | H8: EMA 9|EMA 50|4 horas
A9: 3 | B9: Media móvil | C9: EMA 9 | D9: Media móvil | E9: EMA 150 | F9: 15 min | G9: Nivel 3: EMA 9 cruza EMA 150 en 15 min | H9: EMA 9|EMA 150|15 min
A10: 3 | B10: Media móvil | C10: EMA 9 | D10: Media móvil | E10: EMA 150 | F10: 1 hora | G10: Nivel 3: EMA 9 cruza EMA 150 en 1 hora | H10: EMA 9|EMA 150|1 hora
A11: 3 | B11: Media móvil | C11: EMA 9 | D11: Media móvil | E11: EMA 150 | F11: 4 horas | G11: Nivel 3: EMA 9 cruza EMA 150 en 4 horas | H11: EMA 9|EMA 150|4 horas
A12: 4 | B12: Media móvil | C12: EMA 20 | D12: Media móvil | E12: EMA 50 | F12: 15 min | G12: Nivel 4: EMA 20 cruza EMA 50 en 15 min | H12: EMA 20|EMA 50|15 min
A13: 4 | B13: Media móvil | C13: EMA 20 | D13: Media móvil | E13: EMA 50 | F13: 1 hora | G13: Nivel 4: EMA 20 cruza EMA 50 en 1 hora | H13: EMA 20|EMA 50|1 hora
A14: 4 | B14: Media móvil | C14: EMA 20 | D14: Media móvil | E14: EMA 50 | F14: 4 horas | G14: Nivel 4: EMA 20 cruza EMA 50 en 4 horas | H14: EMA 20|EMA 50|4 horas
... A20: 6 | B20: Media móvil | C20: EMA 50 | D20: Media móvil | E20: EMA 150 | F20: 4 horas | G20: Nivel 6: EMA 50 cruza EMA 150 en 4 horas | H20: EMA 50|EMA 150|4 horas
A21: 7 | B21: Media móvil | C21: EMA 200 | D21: Vela | E21: Vela | F21: 4 horas | G21: Nivel 6: EMA 50 cruza EMA 150 en 4 horas | H21: =IF(C21="","",C21&"|"&E21&"|"&F21) -> EMA 200|Vela|4 horas
H22: =IF(C22="","",C22&"|"&E22&"|"&F22)
H23: =IF(C23="","",C23&"|"&E23&"|"&F23)
H24: =IF(C24="","",C24&"|"&E24&"|"&F24)
H25: =IF(C25="","",C25&"|"&E25&"|"&F25)
H26: =IF(C26="","",C26&"|"&E26&"|"&F26)
H27: =IF(C27="","",C27&"|"&E27&"|"&F27)
H28: =IF(C28="","",C28&"|"&E28&"|"&F28)
H29: =IF(C29="","",C29&"|"&E29&"|"&F29)
H30: =IF(C30="","",C30&"|"&E30&"|"&F30)

Sheet Universo_Activos
A1: Universo maestro de activos seleccionables. Filas PENDIENTE de vincular son plantilla: sustituir Nombre/Ticker/ISIN por el activo real y cambiar Estado a Activo antes de usarlo.
A2: Categoria | B2: Mercado/Bolsa | C2: Nombre del activo | D2: Ticker/Simbolo | E2: ISIN | F2: Divisa | G2: Fuente de datos recomendada | H2: Estado
A3: Acciones Espana | B3: BME (Madrid) | C3: Inditex | D3: ITX.MC | E3: ES0148396007 | F3: EUR | G3: Proveedor API (a configurar) | H3: Activo
A4: Acciones Espana | B4: BME (Madrid) | C4: Iberdrola | D4: IBE.MC | E4: ES0144580Y14 | F4: EUR | G4: Proveedor API (a configurar) | H4: Activo
A5: Acciones Espana | B5: BME (Madrid) | C5: Banco Santander | D5: SAN.MC | E5: ES0113900J37 | F5: EUR | G5: Proveedor API (a configurar) | H5: Activo
A6: Acciones Europa | B6: Euronext Paris | C6: LVMH | D6: MC.PA | E6: FR0000121014 | F6: EUR | G6: Proveedor API (a configurar) | H6: Activo
A7: Acciones Europa | B7: XETRA | C7: SAP | D7: SAP.DE | E7: DE0007164600 | F7: EUR | G7: Proveedor API (a configurar) | H7: Activo
A8: Acciones USA | B8: NASDAQ | C8: Apple Inc. | D8: AAPL | E8: US0378331005 | F8: USD | G8: Proveedor API (a configurar) | H8: Activo
A9: Acciones USA | B9: NASDAQ | C9: Microsoft Corp. | D9: MSFT | E9: US5949181045 | F9: USD | G9: Proveedor API (a configurar) | H9: Activo
A10: Acciones USA | B10: NASDAQ | C10: Tesla Inc. | D10: TSLA | E10: US88160R1014 | F10: USD | G10: Proveedor API (a configurar) | H10: Activo
A11: Forex | B11: OTC/Interbancario | C11: Euro / Dolar | D11: EURUSD | E11: N/A (par de divisas, sin ISIN) | F11: USD | G11: Proveedor Forex (a configurar) | H11: Activo
A12: Forex | B12: OTC/Interbancario | C12: Libra / Dolar | D12: GBPUSD | E12: N/A (par de divisas, sin ISIN) | F12: USD | G12: Proveedor Forex (a configurar) | H12: Activo
A13: Criptomonedas | B13: Exchange Cripto | C13: Bitcoin | D13: BTCUSD | E13: N/A (criptoactivo, sin ISIN) | F13: USD | G13: Proveedor Cripto (a configurar) | H13: Activo
... A15: ETF | B15: NYSE Arca | C15: SPDR S&P 500 ETF | D15: SPY | E15: US78462F1030 | F15: USD | G15: Proveedor API (a configurar) | H15: Activo
A16: Metales | B16: COMEX | C16: Oro (Futuro) | D16: GC=F | F16: USD | G16: Proveedor Futuros (a configurar) | H16: Activo
A17: Metales | B17: COMEX | C17: Plata (Futuro) | D17: SI=F | F17: USD | G17: Proveedor Futuros (a configurar) | H17: Activo
A18: Energia | B18: NYMEX | C18: Gas Natural (Futuro) | D18: NG=F | F18: USD | G18: Proveedor Futuros (a configurar) | H18: Activo
A19: Petroleo | B19: NYMEX | C19: Petroleo WTI (Futuro) | D19: CL=F | F19: USD | G19: Proveedor Futuros (a configurar) | H19: Activo
A20: Petroleo | B20: ICE | C20: Petroleo Brent (Futuro) | D20: BZ=F | F20: USD | G20: Proveedor Futuros (a configurar) | H20: Activo
A21: Cafe | B21: ICE | C21: Cafe Arabica (Futuro) | D21: KC=F | F21: USD | G21: Proveedor Futuros (a configurar) | H21: Activo
A22: Otros commodities | B22: CBOT | C22: Trigo (Futuro) | D22: ZW=F | F22: USD | G22: Proveedor Futuros (a configurar) | H22: Activo
A23: Acciones Espana | B23: BME (Madrid) | C23: Banco Santander | D23: SAN.MC | E23: ES0113900J37 | F23: EUR | G23: Proveedor API (a configurar) | H23: Activo
A24: Acciones Espana | B24: BME (Madrid) | C24: BBVA | D24: BBVA.MC | E24: ES0113211835 | F24: EUR | G24: Proveedor API (a configurar) | H24: Activo
A25: Acciones Espana | B25: BME (Madrid) | C25: Iberdrola | D25: IBE.MC | E25: ES0144580Y14 | F25: EUR | G25: Proveedor API (a configurar) | H25: Activo
A26: Acciones Espana | B26: BME (Madrid) | C26: Inditex | D26: ITX.MC | E26: ES0148260031 | F26: EUR | G26: Proveedor API (a configurar) | H26: Activo
A27: Acciones Espana | B27: BME (Madrid) | C27: Telefónica | D27: TEF.MC | E27: ES0178430E18 | F27: EUR | G27: Proveedor API (a configurar) | H27: Activo
A28: Acciones Espana | B28: BME (Madrid) | C28: Repsol | D28: REP.MC | E28: ES0173516115 | F28: EUR | G28: Proveedor API (a configurar) | H28: Activo
A29: Acciones Espana | B29: BME (Madrid) | C29: CaixaBank | D29: CABK.MC | E29: ES0140609019 | F29: EUR | G29: Proveedor API (a configurar) | H29: Activo
A30: Acciones Espana | B30: BME (Madrid) | C30: Ferrovial | D30: FER.MC | E30: NL0015001M62 | F30: EUR | G30: Proveedor API (a configurar) | H30: Activo
A31: Acciones Espana | B31: BME (Madrid) | C31: Amadeus | D31: AMS.MC | E31: ES0109067019 | F31: EUR | G31: Proveedor API (a configurar) | H31: Activo
A32: Acciones Espana | B32: BME (Madrid) | C32: Cellnex Telecom | D32: CLNX.MC | E32: ES0105066007 | F32: EUR | G32: Proveedor API (a configurar) | H32: Activo
A33: Acciones Espana | B33: BME (Madrid) | C33: Banco Sabadell | D33: SAB.MC | E33: ES0113860A34 | F33: EUR | G33: Proveedor API (a configurar) | H33: Activo
A34: Acciones Espana | B34: BME (Madrid) | C34: ACS | D34: ACS.MC | E34: ES0167050915 | F34: EUR | G34: Proveedor API (a configurar) | H34: Activo
... A629: Acciones Europa | B629: Euronext Amsterdam | C629: Corbion | D629: EURONEXT:CRBN | E629: NL0010583399 | F629: EUR | G629: Euronext / proveedor API (a configurar) (indice compuesto por solo 25 valores; se listan todos) | H629: Activo
A630: Acciones USA | B630: NYSE/NASDAQ | C630: Acciones USA - Activo 0398 (PENDIENTE de vincular) | D630: AU0398 | F630: USD | G630: Proveedor API (a configurar) | H630: Pendiente de configurar
A631: Acciones USA | B631: NYSE/NASDAQ | C631: Acciones USA - Activo 0399 (PENDIENTE de vincular) | D631: AU0399 | F631: USD | G631: Proveedor API (a configurar) | H631: Pendiente de configurar
A632: Acciones USA | B632: NYSE/NASDAQ | C632: Acciones USA - Activo 0400 (PENDIENTE de vincular) | D632: AU0400 | F632: USD | G632: Proveedor API (a configurar) | H632: Pendiente de configurar
A633: Forex | B633: OTC/Interbancario | C633: Forex - Activo 0001 (PENDIENTE de vincular) | D633: F0001 | F633: USD | G633: Proveedor API (a configurar) | H633: Pendiente de configurar
A634: Forex | B634: OTC/Interbancario | C634: Forex - Activo 0002 (PENDIENTE de vincular) | D634: F0002 | F634: USD | G634: Proveedor API (a configurar) | H634: Pendiente de configurar
A635: Forex | B635: OTC/Interbancario | C635: Forex - Activo 0003 (PENDIENTE de vincular) | D635: F0003 | F635: USD | G635: Proveedor API (a configurar) | H635: Pendiente de configurar
...

Sheet Historico_Alertas
B1: HISTORICO DE ALERTAS (todas las combinaciones de cruce evaluadas)
B2: En una implementacion real, una macro VBA (ver documento tecnico) añade una fila nueva aqui cada vez que se detecta un cruce nuevo, evitando duplicados mediante el ID unico.
A4: ID unico | B4: Fecha/Hora deteccion | C4: Activo | D4: Mercado | E4: Time Frame | F4: Tipo de cruce | G4: Elementos cruzados | H4: Direccion | I4: Nivel importancia | J4: Mensaje generado | K4: Estado
A5: =IF(Monitorizacion!$W$12="","",Monitorizacion!$B$12&"|15 min|Vela/Media|"&TEXT(NOW(),"yyyymmddhhmm")) | B5: =IF(Monitorizacion!$W$12="","",TEXT(NOW(),"dd/mm/yyyy hh:mm")) | C5: =IF(Monitorizacion!$W$12="","",Monitorizacion!$B$12) | D5: =IF(Monitorizacion!$W$12="","",Monitorizacion!$D$12) | E5: =IF(Monitorizacion!$W$12="","","15 min") | F5: =IF(Monitorizacion!$W$12="","","Vela/Media") | G5: =IF(Monitorizacion!$W$12="","","Vela vs "&Monitorizacion!$E$5) | H5: =IF(Monitorizacion!$W$12="","",Monitorizacion!$W$12) | I5: =IF(Monitorizacion!$W$12="","",Monitorizacion!$AK$12) | J5: =IF(Monitorizacion!$W$12="","",Monitorizacion!$AL$12) | K5: =IF(Monitorizacion!$W$12="","","Nuevo")
A6: =IF(Monitorizacion!$X$12="","",Monitorizacion!$B$12&"|15 min|Media/Media|"&TEXT(NOW(),"yyyymmddhhmm")) | B6: =IF(Monitorizacion!$X$12="","",TEXT(NOW(),"dd/mm/yyyy hh:mm")) | C6: =IF(Monitorizacion!$X$12="","",Monitorizacion!$B$12) | D6: =IF(Monitorizacion!$X$12="","",Monitorizacion!$D$12) | E6: =IF(Monitorizacion!$X$12="","","15 min") | F6: =IF(Monitorizacion!$X$12="","","Media/Media") | G6: =IF(Monitorizacion!$X$12="","",Monitorizacion!$E$5&" vs "&Monitorizacion!$E$6) | H6: =IF(Monitorizacion!$X$12="","",Monitorizacion!$X$12) | I6: =IF(Monitorizacion!$X$12="","",Monitorizacion!$AK$12) | J6: =IF(Monitorizacion!$X$12="","",Monitorizacion!$AL$12) | K6: =IF(Monitorizacion!$X$12="","","Nuevo")
A7: =IF(Monitorizacion!$AI$12="","",Monitorizacion!$B$12&"|1 hora|Vela/Media|"&TEXT(NOW(),"yyyymmddhhmm")) | B7: =IF(Monitorizacion!$AI$12="","",TEXT(NOW(),"dd/mm/yyyy hh:mm")) | C7: =IF(Monitorizacion!$AI$12="","",Monitorizacion!$B$12) | D7: =IF(Monitorizacion!$AI$12="","",Monitorizacion!$D$12) | E7: =IF(Monitorizacion!$AI$12="","","1 hora") | F7: =IF(Monitorizacion!$AI$12="","","Vela/Media") | G7: =IF(Monitorizacion!$AI$12="","","Vela vs "&Monitorizacion!$E$5) | H7: =IF(Monitorizacion!$AI$12="","",Monitorizacion!$AI$12) | I7: =IF(Monitorizacion!$AI$12="","",Monitorizacion!$AK$12) | J7: =IF(Monitorizacion!$AI$12="","",Monitorizacion!$AL$12) | K7: =IF(Monitorizacion!$AI$12="","","Nuevo")
A8: =IF(Monitorizacion!$AJ$12="","",Monitorizacion!$B$12&"|1 hora|Media/Media|"&TEXT(NOW(),"yyyymmddhhmm")) | B8: =IF(Monitorizacion!$AJ$12="","",TEXT(NOW(),"dd/mm/yyyy hh:mm")) | C8: =IF(Monitorizacion!$AJ$12="","",Monitorizacion!$B$12) | D8: =IF(Monitorizacion!$AJ$12="","",Monitorizacion!$D$12) | E8: =IF(Monitorizacion!$AJ$12="","","1 hora") | F8: =IF(Monitorizacion!$AJ$12="","","Media/Media") | G8: =IF(Monitorizacion!$AJ$12="","",Monitorizacion!$E$5&" vs "&Monitorizacion!$E$6) | H8: =IF(Monitorizacion!$AJ$12="","",Monitorizacion!$AJ$12) | I8: =IF(Monitorizacion!$AJ$12="","",Monitorizacion!$AK$12) | J8: =IF(Monitorizacion!$AJ$12="","",Monitorizacion!$AL$12) | K8: =IF(Monitorizacion!$AJ$12="","","Nuevo")
A9: =IF(Monitorizacion!$W$13="","",Monitorizacion!$B$13&"|15 min|Vela/Media|"&TEXT(NOW(),"yyyymmddhhmm")) | B9: =IF(Monitorizacion!$W$13="","",TEXT(NOW(),"dd/mm/yyyy hh:mm")) | C9: =IF(Monitorizacion!$W$13="","",Monitorizacion!$B$13) | D9: =IF(Monitorizacion!$W$13="","",Monitorizacion!$D$13) | E9: =IF(Monitorizacion!$W$13="","","15 min") | F9: =IF(Monitorizacion!$W$13="","","Vela/Media") | G9: =IF(Monitorizacion!$W$13="","","Vela vs "&Monitorizacion!$E$5) | H9: =IF(Monitorizacion!$W$13="","",Monitorizacion!$W$13) | I9: =IF(Monitorizacion!$W$13="","",Monitorizacion!$AK$13) | J9: =IF(Monitorizacion!$W$13="","",Monitorizacion!$AL$13) | K9: =IF(Monitorizacion!$W$13="","","Nuevo")
A10: =IF(Monitorizacion!$X$13="","",Monitorizacion!$B$13&"|15 min|Media/Media|"&TEXT(NOW(),"yyyymmddhhmm")) | B10: =IF(Monitorizacion!$X$13="","",TEXT(NOW(),"dd/mm/yyyy hh:mm")) | C10: =IF(Monitorizacion!$X$13="","",Monitorizacion!$B$13) | D10: =IF(Monitorizacion!$X$13="","",Monitorizacion!$D$13) | E10: =IF(Monitorizacion!$X$13="","","15 min") | F10: =IF(Monitorizacion!$X$13="","","Media/Media") | G10: =IF(Monitorizacion!$X$13="","",Monitorizacion!$E$5&" vs "&Monitorizacion!$E$6) | H10: =IF(Monitorizacion!$X$13="","",Monitorizacion!$X$13) | I10: =IF(Monitorizacion!$X$13="","",Monitorizacion!$AK$13) | J10: =IF(Monitorizacion!$X$13="","",Monitorizacion!$AL$13) | K10: =IF(Monitorizacion!$X$13="","","Nuevo")
